Traceback (most recent call last):
  File "/home/jjquek/Desktop/msc_computing/indiv-project/msc-project-experiments/experiments-repo/my_venv/lib/python3.8/site-packages/jupyter_cache/executors/utils.py", line 51, in single_nb_execution
    executenb(
  File "/home/jjquek/Desktop/msc_computing/indiv-project/msc-project-experiments/experiments-repo/my_venv/lib/python3.8/site-packages/nbclient/client.py", line 1204, in execute
    return NotebookClient(nb=nb, resources=resources, km=km, **kwargs).execute()
  File "/home/jjquek/Desktop/msc_computing/indiv-project/msc-project-experiments/experiments-repo/my_venv/lib/python3.8/site-packages/nbclient/util.py", line 84, in wrapped
    return just_run(coro(*args, **kwargs))
  File "/home/jjquek/Desktop/msc_computing/indiv-project/msc-project-experiments/experiments-repo/my_venv/lib/python3.8/site-packages/nbclient/util.py", line 62, in just_run
    return loop.run_until_complete(coro)
  File "/usr/lib/python3.8/asyncio/base_events.py", line 616, in run_until_complete
    return future.result()
  File "/home/jjquek/Desktop/msc_computing/indiv-project/msc-project-experiments/experiments-repo/my_venv/lib/python3.8/site-packages/nbclient/client.py", line 663, in async_execute
    await self.async_execute_cell(
  File "/home/jjquek/Desktop/msc_computing/indiv-project/msc-project-experiments/experiments-repo/my_venv/lib/python3.8/site-packages/nbclient/client.py", line 965, in async_execute_cell
    await self._check_raise_for_error(cell, cell_index, exec_reply)
  File "/home/jjquek/Desktop/msc_computing/indiv-project/msc-project-experiments/experiments-repo/my_venv/lib/python3.8/site-packages/nbclient/client.py", line 862, in _check_raise_for_error
    raise CellExecutionError.from_cell_and_msg(cell, exec_reply_content)
nbclient.exceptions.CellExecutionError: An error occurred while executing the following cell:
------------------

# SET UP - Create raw feature vectors 

import torch
import numpy as np
    # for reproducibility
torch.manual_seed(0)

    # CONSTANTS for a run of the Protocol
NUMBER_OF_USERS = 3
NUMBER_OF_FEATURES_PER_USER_VECTOR = 2
VECTOR_SHAPE = (NUMBER_OF_FEATURES_PER_USER_VECTOR, 1)
# TODO: actually, VECTOR_SHAPE is redundant. That wasn't the source of the error. But, anyways.
 
raw_feature_vectors = {}

for i in range(NUMBER_OF_USERS):
    raw_feature_vectors[i] = torch.rand(VECTOR_SHAPE)
    print(f"Here are is the feature vector for user {i}: ")
    print(raw_feature_vectors[i])
    print("\n")
------------------

[0;31m---------------------------------------------------------------------------[0m
[0;31mModuleNotFoundError[0m                       Traceback (most recent call last)
Input [0;32mIn [1][0m, in [0;36m<cell line: 3>[0;34m()[0m
[1;32m      1[0m [38;5;66;03m# SET UP - Create raw feature vectors [39;00m
[0;32m----> 3[0m [38;5;28;01mimport[39;00m [38;5;21;01mtorch[39;00m
[1;32m      4[0m [38;5;28;01mimport[39;00m [38;5;21;01mnumpy[39;00m [38;5;28;01mas[39;00m [38;5;21;01mnp[39;00m
[1;32m      5[0m     [38;5;66;03m# for reproducibility[39;00m

[0;31mModuleNotFoundError[0m: No module named 'torch'
ModuleNotFoundError: No module named 'torch'

